<?xml version="1.0" encoding="utf-8"?>
<!-- This URDF was automatically created by SolidWorks to URDF Exporter! Originally created by Stephen Brawner (brawner@gmail.com) 
     Commit Version: 1.6.0-4-g7f85cfe  Build Version: 1.6.7995.38578
     For more information, please see http://wiki.ros.org/sw_urdf_exporter -->
<robot
  name="Kable_Hand">
  <link
    name="base_link">
    <inertial>
      <origin
        xyz="-0.032744 -0.013118 0.018371"
        rpy="0 0 0" />
      <mass
        value="0.29085" />
      <inertia
        ixx="0.00018237"
        ixy="3.7275E-05"
        ixz="1.6016E-06"
        iyy="0.00031716"
        iyz="-1.1094E-05"
        izz="0.00018376" />
    </inertial>
    <visual>
      <origin
        xyz="0 0 0"
        rpy="0 0 0" />
      <geometry>
        <mesh
          filename="../meshes/base_link.STL" />
      </geometry>
      <material
        name="">
        <color
          rgba="0.89804 0.91765 0.92941 1" />
      </material>
    </visual>
    <collision>
      <origin
        xyz="0 0 0"
        rpy="0 0 0" />
      <geometry>
        <mesh
          filename="../meshes/base_link.STL" />
      </geometry>
    </collision>
  </link>
  <link
    name="Gear_Link1">
    <inertial>
      <origin
        xyz="3.21235971656453E-07 -3.321260095418E-08 -0.000970165037561699"
        rpy="0 0 0" />
      <mass
        value="0.00492029859718589" />
      <inertia
        ixx="7.15517939042466E-08"
        ixy="1.08297969210548E-09"
        ixz="-1.11935671116004E-12"
        iyy="7.14849036552842E-08"
        iyz="-1.03875202755291E-12"
        izz="6.79250460692256E-08" />
    </inertial>
    <visual>
      <origin
        xyz="0 0 0"
        rpy="0 0 0" />
      <geometry>
        <mesh
          filename="../meshes/Gear_Link1.STL" />
      </geometry>
      <material
        name="">
        <color
          rgba="0.317647058823529 0.247058823529412 0.207843137254902 1" />
      </material>
    </visual>
    <collision>
      <origin
        xyz="0 0 0"
        rpy="0 0 0" />
      <geometry>
        <mesh
          filename="../meshes/Gear_Link1.STL" />
      </geometry>
    </collision>
  </link>
  <joint
    name="Gear_Joint1"
    type="revolute">
    <origin
      xyz="-0.065517 0.002731 -0.026815"
      rpy="-1.7585 1.0421 -1.9901" />
    <parent
      link="base_link" />
    <child
      link="Gear_Link1" />
    <axis
      xyz="0 0 -1" />
    <limit
      lower="0"
      upper="3.8397"
      effort="0"
      velocity="0" />
  </joint>
  <link
    name="Gear_Link2">
    <inertial>
      <origin
        xyz="3.215E-07 -3.0764E-08 -0.00097016"
        rpy="0 0 0" />
      <mass
        value="0.0049203" />
      <inertia
        ixx="7.1552E-08"
        ixy="1.083E-09"
        ixz="-1.1056E-12"
        iyy="7.1485E-08"
        iyz="-1.0308E-12"
        izz="6.7925E-08" />
    </inertial>
    <visual>
      <origin
        xyz="0 0 0"
        rpy="0 0 0" />
      <geometry>
        <mesh
          filename="../meshes/Gear_Link2.STL" />
      </geometry>
      <material
        name="">
        <color
          rgba="0.31765 0.24706 0.20784 1" />
      </material>
    </visual>
    <collision>
      <origin
        xyz="0 0 0"
        rpy="0 0 0" />
      <geometry>
        <mesh
          filename="../meshes/Gear_Link2.STL" />
      </geometry>
    </collision>
  </link>
  <joint
    name="Gear_Joint2"
    type="revolute">
    <origin
      xyz="-0.045112 -0.0026274 -0.035619"
      rpy="-1.6965 1.0464 -1.9366" />
    <parent
      link="base_link" />
    <child
      link="Gear_Link2" />
    <axis
      xyz="0 0 -1" />
    <limit
      lower="0"
      upper="3.8397"
      effort="0"
      velocity="0" />
  </joint>
  <link
    name="Gear_Link3">
    <inertial>
      <origin
        xyz="2.0285E-07 1.9533E-07 -0.00097016"
        rpy="0 0 0" />
      <mass
        value="0.0049203" />
      <inertia
        ixx="7.1552E-08"
        ixy="1.083E-09"
        ixz="-1.0652E-12"
        iyy="7.1485E-08"
        iyz="-1.0045E-12"
        izz="6.7925E-08" />
    </inertial>
    <visual>
      <origin
        xyz="0 0 0"
        rpy="0 0 0" />
      <geometry>
        <mesh
          filename="../meshes/Gear_Link3.STL" />
      </geometry>
      <material
        name="">
        <color
          rgba="0.31765 0.24706 0.20784 1" />
      </material>
    </visual>
    <collision>
      <origin
        xyz="0 0 0"
        rpy="0 0 0" />
      <geometry>
        <mesh
          filename="../meshes/Gear_Link3.STL" />
      </geometry>
    </collision>
  </link>
  <joint
    name="Gear_Joint3"
    type="revolute">
    <origin
      xyz="-0.024133 -0.0081371 -0.040426"
      rpy="-1.6339 1.0489 -1.8823" />
    <parent
      link="base_link" />
    <child
      link="Gear_Link3" />
    <axis
      xyz="0 0 -1" />
    <limit
      lower="0"
      upper="3.8397"
      effort="0"
      velocity="0" />
  </joint>
  <link
    name="Gear_Link4">
    <inertial>
      <origin
        xyz="3.3395E-07 -1.7285E-08 -0.00097016"
        rpy="0 0 0" />
      <mass
        value="0.0049203" />
      <inertia
        ixx="7.1552E-08"
        ixy="1.083E-09"
        ixz="-1.0307E-12"
        iyy="7.1485E-08"
        iyz="-9.7987E-13"
        izz="6.7925E-08" />
    </inertial>
    <visual>
      <origin
        xyz="0 0 0"
        rpy="0 0 0" />
      <geometry>
        <mesh
          filename="../meshes/Gear_Link4.STL" />
      </geometry>
      <material
        name="">
        <color
          rgba="0.89804 0.91765 0.92941 1" />
      </material>
    </visual>
    <collision>
      <origin
        xyz="0 0 0"
        rpy="0 0 0" />
      <geometry>
        <mesh
          filename="../meshes/Gear_Link4.STL" />
      </geometry>
    </collision>
  </link>
  <joint
    name="Gear_Joint4"
    type="revolute">
    <origin
      xyz="-0.0029031 -0.013712 -0.03599"
      rpy="-1.5708 1.0498 -1.8276" />
    <parent
      link="base_link" />
    <child
      link="Gear_Link4" />
    <axis
      xyz="0 0 -1" />
    <limit
      lower="0"
      upper="3.8397"
      effort="0"
      velocity="0" />
  </joint>
  <link
    name="Thumb_Side_Gear_Link">
    <inertial>
      <origin
        xyz="0.010087 0.0025106 0.0052169"
        rpy="0 0 0" />
      <mass
        value="0.025787" />
      <inertia
        ixx="2.2707E-06"
        ixy="-3.1994E-09"
        ixz="-2.8841E-07"
        iyy="3.6185E-06"
        iyz="2.1872E-08"
        izz="3.0855E-06" />
    </inertial>
    <visual>
      <origin
        xyz="0 0 0"
        rpy="0 0 0" />
      <geometry>
        <mesh
          filename="../meshes/Thumb_Side_Gear_Link.STL" />
      </geometry>
      <material
        name="">
        <color
          rgba="0.31765 0.24706 0.20784 1" />
      </material>
    </visual>
    <collision>
      <origin
        xyz="0 0 0"
        rpy="0 0 0" />
      <geometry>
        <mesh
          filename="../meshes/Thumb_Side_Gear_Link.STL" />
      </geometry>
    </collision>
  </link>
  <joint
    name="Thumb_Side_Gear_Joint"
    type="revolute">
    <origin
      xyz="0 0 0"
      rpy="0 0 0" />
    <parent
      link="base_link" />
    <child
      link="Thumb_Side_Gear_Link" />
    <axis
      xyz="0 0 1" />
    <limit
      lower="0"
      upper="1.57"
      effort="0"
      velocity="0" />
  </joint>
  <link
    name="Thumb_Link1">
    <inertial>
      <origin
        xyz="0.025498 -0.00019689 -4.4958E-05"
        rpy="0 0 0" />
      <mass
        value="0.025004" />
      <inertia
        ixx="9.4677E-07"
        ixy="-7.8812E-08"
        ixz="2.6974E-08"
        iyy="4.7012E-06"
        iyz="6.3749E-09"
        izz="4.981E-06" />
    </inertial>
    <visual>
      <origin
        xyz="0 0 0"
        rpy="0 0 0" />
      <geometry>
        <mesh
          filename="../meshes/Thumb_Link1.STL" />
      </geometry>
      <material
        name="">
        <color
          rgba="0.89804 0.91765 0.92941 1" />
      </material>
    </visual>
    <collision>
      <origin
        xyz="0 0 0"
        rpy="0 0 0" />
      <geometry>
        <mesh
          filename="../meshes/Thumb_Link1.STL" />
      </geometry>
    </collision>
  </link>
  <joint
    name="Thumb_Joint1"
    type="revolute">
    <origin
      xyz="0.029921 0 0"
      rpy="-1.5708 0.031418 -0.25681" />
    <parent
      link="Thumb_Side_Gear_Link" />
    <child
      link="Thumb_Link1" />
    <axis
      xyz="0 0 -1" />
    <limit
      lower="0"
      upper="1.396"
      effort="0"
      velocity="0" />
    <mimic
      joint="Thumb_Gear_Joint"
      multiplier="0.4774"
      offset="0.18" />
  </joint>
  <link
    name="Thumb_Link2">
    <inertial>
      <origin
        xyz="0.020026 -0.0068153 -6.9655E-05"
        rpy="0 0 0" />
      <mass
        value="0.015561" />
      <inertia
        ixx="5.7593E-07"
        ixy="4.7614E-07"
        ixz="2.7255E-10"
        iyy="1.9292E-06"
        iyz="1.9242E-09"
        izz="2.1112E-06" />
    </inertial>
    <visual>
      <origin
        xyz="0 0 0"
        rpy="0 0 0" />
      <geometry>
        <mesh
          filename="../meshes/Thumb_Link2.STL" />
      </geometry>
      <material
        name="">
        <color
          rgba="0.89804 0.91765 0.92941 1" />
      </material>
    </visual>
    <collision>
      <origin
        xyz="0 0 0"
        rpy="0 0 0" />
      <geometry>
        <mesh
          filename="../meshes/Thumb_Link2.STL" />
      </geometry>
    </collision>
  </link>
  <joint
    name="Thumb_Joint2"
    type="revolute">
    <origin
      xyz="0.044515 0.0015319 0"
      rpy="0 0 0.5463" />
    <parent
      link="Thumb_Link1" />
    <child
      link="Thumb_Link2" />
    <axis
      xyz="0 0 -1" />
    <limit
      lower="0"
      upper="1.396"
      effort="0"
      velocity="0" />
    <mimic
      joint="Thumb_Gear_Joint"
      multiplier="0.49346"
      offset="0" />
  </joint>
  <link
    name="Thumb_Gear_Link">
    <inertial>
      <origin
        xyz="4.1326E-05 0.00015812 -0.00093746"
        rpy="0 0 0" />
      <mass
        value="0.007631" />
      <inertia
        ixx="1.4284E-07"
        ixy="3.1947E-10"
        ixz="1.6879E-12"
        iyy="1.4397E-07"
        iyz="-3.851E-13"
        izz="2.19E-07" />
    </inertial>
    <visual>
      <origin
        xyz="0 0 0"
        rpy="0 0 0" />
      <geometry>
        <mesh
          filename="../meshes/Thumb_Gear_Link.STL" />
      </geometry>
      <material
        name="">
        <color
          rgba="0.31765 0.24706 0.20784 1" />
      </material>
    </visual>
    <collision>
      <origin
        xyz="0 0 0"
        rpy="0 0 0" />
      <geometry>
        <mesh
          filename="../meshes/Thumb_Gear_Link.STL" />
      </geometry>
    </collision>
  </link>
  <joint
    name="Thumb_Gear_Joint"
    type="revolute">
    <origin
      xyz="0 0 0"
      rpy="0 0 0" />
    <parent
      link="base_link" />
    <child
      link="Thumb_Gear_Link" />
    <axis
      xyz="0 0 1" />
    <limit
      lower="0"
      upper="2.8293"
      effort="0"
      velocity="0" />
  </joint>
  <link
    name="Finger1_Link1">
    <inertial>
      <origin
        xyz="0.025476 -0.0010737 -4.4951E-05"
        rpy="0 0 0" />
      <mass
        value="0.025004" />
      <inertia
        ixx="9.4579E-07"
        ixy="5.0405E-08"
        ixz="2.7184E-08"
        iyy="4.7022E-06"
        iyz="5.4485E-09"
        izz="4.981E-06" />
    </inertial>
    <visual>
      <origin
        xyz="0 0 0"
        rpy="0 0 0" />
      <geometry>
        <mesh
          filename="../meshes/Finger1_Link1.STL" />
      </geometry>
      <material
        name="">
        <color
          rgba="0.89804 0.91765 0.92941 1" />
      </material>
    </visual>
    <collision>
      <origin
        xyz="0 0 0"
        rpy="0 0 0" />
      <geometry>
        <mesh
          filename="../meshes/Finger1_Link1.STL" />
      </geometry>
    </collision>
  </link>
  <joint
    name="Finger1_Joint1"
    type="revolute">
    <origin
      xyz="-0.068818 -0.0046734 -0.040694"
      rpy="2.5337 1.4559 2.2738" />
    <parent
      link="base_link" />
    <child
      link="Finger1_Link1" />
    <axis
      xyz="0 0 -1" />
    <limit
      lower="0"
      upper="1.396"
      effort="0"
      velocity="0" />
    <mimic
      joint="Gear_Joint1"
      multiplier="0.35176"
      offset="0.18" />
  </joint>
  <link
    name="Finger1_Link2">
    <inertial>
      <origin
        xyz="0.020025 -0.0068148 -6.9833E-05"
        rpy="0 0 0" />
      <mass
        value="0.01556" />
      <inertia
        ixx="5.7583E-07"
        ixy="4.7604E-07"
        ixz="2.9421E-10"
        iyy="1.9291E-06"
        iyz="1.9089E-09"
        izz="2.111E-06" />
    </inertial>
    <visual>
      <origin
        xyz="0 0 0"
        rpy="0 0 0" />
      <geometry>
        <mesh
          filename="../meshes/Finger1_Link2.STL" />
      </geometry>
      <material
        name="">
        <color
          rgba="0.89804 0.91765 0.92941 1" />
      </material>
    </visual>
    <collision>
      <origin
        xyz="0 0 0"
        rpy="0 0 0" />
      <geometry>
        <mesh
          filename="../meshes/Finger1_Link2.STL" />
      </geometry>
    </collision>
  </link>
  <joint
    name="Finger1_Joint2"
    type="revolute">
    <origin
      xyz="0.044541 0 0"
      rpy="0 0 0.51191" />
    <parent
      link="Finger1_Link1" />
    <child
      link="Finger1_Link2" />
    <axis
      xyz="0 0 -1" />
    <limit
      lower="0"
      upper="1.396"
      effort="0"
      velocity="0" />
    <mimic
      joint="Gear_Joint1"
      multiplier="0.3636"
      offset="0" />
  </joint>
  <link
    name="Finger2_Link1">
    <inertial>
      <origin
        xyz="0.025476 -0.0010737 -4.4938E-05"
        rpy="0 0 0" />
      <mass
        value="0.025004" />
      <inertia
        ixx="9.4579E-07"
        ixy="5.0406E-08"
        ixz="2.7183E-08"
        iyy="4.7022E-06"
        iyz="5.4488E-09"
        izz="4.981E-06" />
    </inertial>
    <visual>
      <origin
        xyz="0 0 0"
        rpy="0 0 0" />
      <geometry>
        <mesh
          filename="../meshes/Finger2_Link1.STL" />
      </geometry>
      <material
        name="">
        <color
          rgba="0.89804 0.91765 0.92941 1" />
      </material>
    </visual>
    <collision>
      <origin
        xyz="0 0 0"
        rpy="0 0 0" />
      <geometry>
        <mesh
          filename="../meshes/Finger2_Link1.STL" />
      </geometry>
    </collision>
  </link>
  <joint
    name="Finger2_Joint1"
    type="revolute">
    <origin
      xyz="-0.047991 -0.010143 -0.049531"
      rpy="2.334 1.4798 2.0751" />
    <parent
      link="base_link" />
    <child
      link="Finger2_Link1" />
    <axis
      xyz="0 0 -1" />
    <limit
      lower="0"
      upper="1.396"
      effort="0"
      velocity="0" />
    <mimic
      joint="Gear_Joint2"
      multiplier="0.35176"
      offset="0.18" />
  </joint>
  <link
    name="Finger2_Link2">
    <inertial>
      <origin
        xyz="0.0200258743515887 -0.00681524058208692 -6.9645381510039E-05"
        rpy="0 0 0" />
      <mass
        value="0.0155610418061381" />
      <inertia
        ixx="5.75913178279493E-07"
        ixy="4.76135574514719E-07"
        ixz="2.64568846571697E-10"
        iyy="1.92921986268351E-06"
        iyz="1.92872157346128E-09"
        izz="2.11120983189749E-06" />
    </inertial>
    <visual>
      <origin
        xyz="0 0 0"
        rpy="0 0 0" />
      <geometry>
        <mesh
          filename="../meshes/Finger2_Link2.STL" />
      </geometry>
      <material
        name="">
        <color
          rgba="0.898039215686275 0.917647058823529 0.929411764705882 1" />
      </material>
    </visual>
    <collision>
      <origin
        xyz="0 0 0"
        rpy="0 0 0" />
      <geometry>
        <mesh
          filename="../meshes/Finger2_Link2.STL" />
      </geometry>
    </collision>
  </link>
  <joint
    name="Finger2_Joint2"
    type="revolute">
    <origin
      xyz="0.044541 0 0"
      rpy="0 0 0.51191" />
    <parent
      link="Finger2_Link1" />
    <child
      link="Finger2_Link2" />
    <axis
      xyz="0 0 -1" />
    <limit
      lower="0"
      upper="1.396"
      effort="0"
      velocity="0" />
    <mimic
      joint="Gear_Joint2"
      multiplier="0.3636"
      offset="0" />
  </joint>
  <link
    name="Finger3_Link1">
    <inertial>
      <origin
        xyz="0.025476 -0.0010737 -4.4956E-05"
        rpy="0 0 0" />
      <mass
        value="0.025004" />
      <inertia
        ixx="9.4579E-07"
        ixy="5.0422E-08"
        ixz="2.7177E-08"
        iyy="4.7022E-06"
        iyz="5.4439E-09"
        izz="4.981E-06" />
    </inertial>
    <visual>
      <origin
        xyz="0 0 0"
        rpy="0 0 0" />
      <geometry>
        <mesh
          filename="../meshes/Finger3_Link1.STL" />
      </geometry>
      <material
        name="">
        <color
          rgba="0.89804 0.91765 0.92941 1" />
      </material>
    </visual>
    <collision>
      <origin
        xyz="0 0 0"
        rpy="0 0 0" />
      <geometry>
        <mesh
          filename="../meshes/Finger3_Link1.STL" />
      </geometry>
    </collision>
  </link>
  <joint
    name="Finger3_Joint1"
    type="revolute">
    <origin
      xyz="-0.026589 -0.015763 -0.054359"
      rpy="2.0165 1.4979 1.7587" />
    <parent
      link="base_link" />
    <child
      link="Finger3_Link1" />
    <axis
      xyz="0 0 -1" />
    <limit
      lower="0"
      upper="1.396"
      effort="0"
      velocity="0" />
    <mimic
      joint="Gear_Joint3"
      multiplier="0.35176"
      offset="0.18" />
  </joint>
  <link
    name="Finger3_Link2">
    <inertial>
      <origin
        xyz="0.020026 -0.0068153 -6.9667E-05"
        rpy="0 0 0" />
      <mass
        value="0.015561" />
      <inertia
        ixx="5.7592E-07"
        ixy="4.7614E-07"
        ixz="2.6912E-10"
        iyy="1.9292E-06"
        iyz="1.9252E-09"
        izz="2.1112E-06" />
    </inertial>
    <visual>
      <origin
        xyz="0 0 0"
        rpy="0 0 0" />
      <geometry>
        <mesh
          filename="../meshes/Finger3_Link2.STL" />
      </geometry>
      <material
        name="">
        <color
          rgba="0.89804 0.91765 0.92941 1" />
      </material>
    </visual>
    <collision>
      <origin
        xyz="0 0 0"
        rpy="0 0 0" />
      <geometry>
        <mesh
          filename="../meshes/Finger3_Link2.STL" />
      </geometry>
    </collision>
  </link>
  <joint
    name="Finger3_Joint2"
    type="revolute">
    <origin
      xyz="0.044541 0 0"
      rpy="0 0 0.51191" />
    <parent
      link="Finger3_Link1" />
    <child
      link="Finger3_Link2" />
    <axis
      xyz="0 0 -1" />
    <limit
      lower="0"
      upper="1.396"
      effort="0"
      velocity="0" />
    <mimic
      joint="Gear_Joint3"
      multiplier="0.3636"
      offset="0" />
  </joint>
  <link
    name="Finger4_Link1">
    <inertial>
      <origin
        xyz="0.025476 -0.0010737 -4.4975E-05"
        rpy="0 0 0" />
      <mass
        value="0.025004" />
      <inertia
        ixx="9.4579E-07"
        ixy="5.0406E-08"
        ixz="2.7178E-08"
        iyy="4.7022E-06"
        iyz="5.4442E-09"
        izz="4.981E-06" />
    </inertial>
    <visual>
      <origin
        xyz="0 0 0"
        rpy="0 0 0" />
      <geometry>
        <mesh
          filename="../meshes/Finger4_Link1.STL" />
      </geometry>
      <material
        name="">
        <color
          rgba="0.89804 0.91765 0.92941 1" />
      </material>
    </visual>
    <collision>
      <origin
        xyz="0 0 0"
        rpy="0 0 0" />
      <geometry>
        <mesh
          filename="../meshes/Finger4_Link1.STL" />
      </geometry>
    </collision>
  </link>
  <joint
    name="Finger4_Joint1"
    type="revolute">
    <origin
      xyz="-0.004935 -0.02145 -0.04993"
      rpy="1.5708 1.505 1.314" />
    <parent
      link="base_link" />
    <child
      link="Finger4_Link1" />
    <axis
      xyz="0 0 -1" />
    <limit
      lower="0"
      upper="1.396"
      effort="0"
      velocity="0" />
    <mimic
      joint="Gear_Joint4"
      multiplier="0.35176"
      offset="0.18" />
  </joint>
  <link
    name="Finger4_Link2">
    <inertial>
      <origin
        xyz="0.020026 -0.0068153 -6.9715E-05"
        rpy="0 0 0" />
      <mass
        value="0.015561" />
      <inertia
        ixx="5.7591E-07"
        ixy="4.7614E-07"
        ixz="2.6685E-10"
        iyy="1.9293E-06"
        iyz="1.9265E-09"
        izz="2.1112E-06" />
    </inertial>
    <visual>
      <origin
        xyz="0 0 0"
        rpy="0 0 0" />
      <geometry>
        <mesh
          filename="../meshes/Finger4_Link2.STL" />
      </geometry>
      <material
        name="">
        <color
          rgba="0.89804 0.91765 0.92941 1" />
      </material>
    </visual>
    <collision>
      <origin
        xyz="0 0 0"
        rpy="0 0 0" />
      <geometry>
        <mesh
          filename="../meshes/Finger4_Link2.STL" />
      </geometry>
    </collision>
  </link>
  <joint
    name="Finger4_Joint2"
    type="revolute">
    <origin
      xyz="0.044541 0 0"
      rpy="0 0 0.51191" />
    <parent
      link="Finger4_Link1" />
    <child
      link="Finger4_Link2" />
    <axis
      xyz="0 0 -1" />
    <limit
      lower="0"
      upper="1.396"
      effort="0"
      velocity="0" />
    <mimic
      joint="Gear_Joint4"
      multiplier="0.3636"
      offset="0" />
  </joint>
</robot>